Workbook

Sheet P&L 2026 YTD (Bank)
B2: DMF Automation
B3: Profit & Loss Statement — Year to Date 2026 (Jan–Aug, from bank records)
B4: All figures in EUR. Compiled from actual bank inflows/outflows per the 'BANK RECORDS' tab; see '2026 Bank Transactions' tab for transaction-level detail and category assignment logic.
B6: Category | C6: Jan-Feb 2026 | D6: Mar-Apr 2026 | E6: May-Jun 2026 | F6: Jul-Aug 2026 | G6: Total YTD
B7: Revenue
B8: Sales Revenue | C8: =SUMIFS('2026 Bank Transactions'!$D$2:$D$223,'2026 Bank Transactions'!$A$2:$A$223,"Jan/Feb 2026",'2026 Bank Transactions'!$F$2:$F$223,"Sales Revenue")-SUMIFS('2026 Bank Transactions'!$E$2:$E$223,'2026 Bank Transactions'!$A$2:$A$223,"Jan/Feb 2026",'2026 Bank Transactions'!$F$2:$F$223,"Sales Revenue") -> 5031.93 | D8: =SUMIFS('2026 Bank Transactions'!$D$2:$D$223,'2026 Bank Transactions'!$A$2:$A$223,"Mar/Apr 2026",'2026 Bank Transactions'!$F$2:$F$223,"Sales Revenue")-SUMIFS('2026 Bank Transactions'!$E$2:$E$223,'2026 Bank Transactions'!$A$2:$A$223,"Mar/Apr 2026",'2026 Bank Transactions'!$F$2:$F$223,"Sales Revenue") -> 38246.34 | E8: =SUMIFS('2026 Bank Transactions'!$D$2:$D$223,'2026 Bank Transactions'!$A$2:$A$223,"May/Jun 2026",'2026 Bank Transactions'!$F$2:$F$223,"Sales Revenue")-SUMIFS('2026 Bank Transactions'!$E$2:$E$223,'2026 Bank Transactions'!$A$2:$A$223,"May/Jun 2026",'2026 Bank Transactions'!$F$2:$F$223,"Sales Revenue") -> 40115.49 | F8: =SUMIFS('2026 Bank Transactions'!$D$2:$D$223,'2026 Bank Transactions'!$A$2:$A$223,"Jul/Aug 2026",'2026 Bank Transactions'!$F$2:$F$223,"Sales Revenue")-SUMIFS('2026 Bank Transactions'!$E$2:$E$223,'2026 Bank Transactions'!$A$2:$A$223,"Jul/Aug 2026",'2026 Bank Transactions'!$F$2:$F$223,"Sales Revenue") -> 70005.9 | G8: =SUM(C8:F8) -> 153399.66
B9: VAT Refund | C9: =SUMIFS('2026 Bank Transactions'!$D$2:$D$223,'2026 Bank Transactions'!$A$2:$A$223,"Jan/Feb 2026",'2026 Bank Transactions'!$F$2:$F$223,"VAT Refund")-SUMIFS('2026 Bank Transactions'!$E$2:$E$223,'2026 Bank Transactions'!$A$2:$A$223,"Jan/Feb 2026",'2026 Bank Transactions'!$F$2:$F$223,"VAT Refund") -> 0 | D9: =SUMIFS('2026 Bank Transactions'!$D$2:$D$223,'2026 Bank Transactions'!$A$2:$A$223,"Mar/Apr 2026",'2026 Bank Transactions'!$F$2:$F$223,"VAT Refund")-SUMIFS('2026 Bank Transactions'!$E$2:$E$223,'2026 Bank Transactions'!$A$2:$A$223,"Mar/Apr 2026",'2026 Bank Transactions'!$F$2:$F$223,"VAT Refund") -> 886 | E9: =SUMIFS('2026 Bank Transactions'!$D$2:$D$223,'2026 Bank Transactions'!$A$2:$A$223,"May/Jun 2026",'2026 Bank Transactions'!$F$2:$F$223,"VAT Refund")-SUMIFS('2026 Bank Transactions'!$E$2:$E$223,'2026 Bank Transactions'!$A$2:$A$223,"May/Jun 2026",'2026 Bank Transactions'!$F$2:$F$223,"VAT Refund") -> 0 | F9: =SUMIFS('2026 Bank Transactions'!$D$2:$D$223,'2026 Bank Transactions'!$A$2:$A$223,"Jul/Aug 2026",'2026 Bank Transactions'!$F$2:$F$223,"VAT Refund")-SUMIFS('2026 Bank Transactions'!$E$2:$E$223,'2026 Bank Transactions'!$A$2:$A$223,"Jul/Aug 2026",'2026 Bank Transactions'!$F$2:$F$223,"VAT Refund") -> 0 | G9: =SUM(C9:F9) -> 886
B10: Total Revenue | C10: =SUM(C8:C9) -> 5031.93 | D10: =SUM(D8:D9) -> 39132.34 | E10: =SUM(E8:E9) -> 40115.49 | F10: =SUM(F8:F9) -> 70005.9 | G10: =SUM(C10:F10) -> 154285.66
B12: Cost of Sales
B13: Automation Subcontractors & Suppliers | C13: =SUMIFS('2026 Bank Transactions'!$D$2:$D$223,'2026 Bank Transactions'!$A$2:$A$223,"Jan/Feb 2026",'2026 Bank Transactions'!$F$2:$F$223,"Automation Subcontractors & Suppliers")-SUMIFS('2026 Bank Transactions'!$E$2:$E$223,'2026 Bank Transactions'!$A$2:$A$223,"Jan/Feb 2026",'2026 Bank Transactions'!$F$2:$F$223,"Automation Subcontractors & Suppliers") -> -7272.64 | D13: =SUMIFS('2026 Bank Transactions'!$D$2:$D$223,'2026 Bank Transactions'!$A$2:$A$223,"Mar/Apr 2026",'2026 Bank Transactions'!$F$2:$F$223,"Automation Subcontractors & Suppliers")-SUMIFS('2026 Bank Transactions'!$E$2:$E$223,'2026 Bank Transactions'!$A$2:$A$223,"Mar/Apr 2026",'2026 Bank Transactions'!$F$2:$F$223,"Automation Subcontractors & Suppliers") -> -14432.13 | E13: =SUMIFS('2026 Bank Transactions'!$D$2:$D$223,'2026 Bank Transactions'!$A$2:$A$223,"May/Jun 2026",'2026 Bank Transactions'!$F$2:$F$223,"Automation Subcontractors & Suppliers")-SUMIFS('2026 Bank Transactions'!$E$2:$E$223,'2026 Bank Transactions'!$A$2:$A$223,"May/Jun 2026",'2026 Bank Transactions'!$F$2:$F$223,"Automation Subcontractors & Suppliers") -> -11049.24 | F13: =SUMIFS('2026 Bank Transactions'!$D$2:$D$223,'2026 Bank Transactions'!$A$2:$A$223,"Jul/Aug 2026",'2026 Bank Transactions'!$F$2:$F$223,"Automation Subcontractors & Suppliers")-SUMIFS('2026 Bank Transactions'!$E$2:$E$223,'2026 Bank Transactions'!$A$2:$A$223,"Jul/Aug 2026",'2026 Bank Transactions'!$F$2:$F$223,"Automation Subcontractors & Suppliers") -> -2887.27 | G13: =SUM(C13:F13) -> -35641.28
B14: Materials & Components | C14: =SUMIFS('2026 Bank Transactions'!$D$2:$D$223,'2026 Bank Transactions'!$A$2:$A$223,"Jan/Feb 2026",'2026 Bank Transactions'!$F$2:$F$223,"Materials & Components")-SUMIFS('2026 Bank Transactions'!$E$2:$E$223,'2026 Bank Transactions'!$A$2:$A$223,"Jan/Feb 2026",'2026 Bank Transactions'!$F$2:$F$223,"Materials & Components") -> -1258.92 | D14: =SUMIFS('2026 Bank Transactions'!$D$2:$D$223,'2026 Bank Transactions'!$A$2:$A$223,"Mar/Apr 2026",'2026 Bank Transactions'!$F$2:$F$223,"Materials & Components")-SUMIFS('2026 Bank Transactions'!$E$2:$E$223,'2026 Bank Transactions'!$A$2:$A$223,"Mar/Apr 2026",'2026 Bank Transactions'!$F$2:$F$223,"Materials & Components") -> -4076.96 | E14: =SUMIFS('2026 Bank Transactions'!$D$2:$D$223,'2026 Bank Transactions'!$A$2:$A$223,"May/Jun 2026",'2026 Bank Transactions'!$F$2:$F$223,"Materials & Components")-SUMIFS('2026 Bank Transactions'!$E$2:$E$223,'2026 Bank Transactions'!$A$2:$A$223,"May/Jun 2026",'2026 Bank Transactions'!$F$2:$F$223,"Materials & Components") -> -2031.1 | F14: =SUMIFS('2026 Bank Transactions'!$D$2:$D$223,'2026 Bank Transactions'!$A$2:$A$223,"Jul/Aug 2026",'2026 Bank Transactions'!$F$2:$F$223,"Materials & Components")-SUMIFS('2026 Bank Transactions'!$E$2:$E$223,'2026 Bank Transactions'!$A$2:$A$223,"Jul/Aug 2026",'2026 Bank Transactions'!$F$2:$F$223,"Materials & Components") -> -542.73 | G14: =SUM(C14:F14) -> -7909.71
B15: Total Cost of Sales | C15: =SUM(C13:C14) -> -8531.56 | D15: =SUM(D13:D14) -> -18509.09 | E15: =SUM(E13:E14) -> -13080.34 | F15: =SUM(F13:F14) -> -3430 | G15: =SUM(C15:F15) -> -43550.99
B17: Gross Profit | C17: =C10+C15 -> -3499.63 | D17: =D10+D15 -> 20623.25 | E17: =E10+E15 -> 27035.15 | F17: =F10+F15 -> 66575.9 | G17: =SUM(C17:F17) -> 110734.67
B19: Operating Expenses
B20: Software & IT Subscriptions | C20: =SUMIFS('2026 Bank Transactions'!$D$2:$D$223,'2026 Bank Transactions'!$A$2:$A$223,"Jan/Feb 2026",'2026 Bank Transactions'!$F$2:$F$223,"Software & IT Subscriptions")-SUMIFS('2026 Bank Transactions'!$E$2:$E$223,'2026 Bank Transactions'!$A$2:$A$223,"Jan/Feb 2026",'2026 Bank Transactions'!$F$2:$F$223,"Software & IT Subscriptions") -> -4623.57 | D20: =SUMIFS('2026 Bank Transactions'!$D$2:$D$223,'2026 Bank Transactions'!$A$2:$A$223,"Mar/Apr 2026",'2026 Bank Transactions'!$F$2:$F$223,"Software & IT Subscriptions")-SUMIFS('2026 Bank Transactions'!$E$2:$E$223,'2026 Bank Transactions'!$A$2:$A$223,"Mar/Apr 2026",'2026 Bank Transactions'!$F$2:$F$223,"Software & IT Subscriptions") -> -511.92 | E20: =SUMIFS('2026 Bank Transactions'!$D$2:$D$223,'2026 Bank Transactions'!$A$2:$A$223,"May/Jun 2026",'2026 Bank Transactions'!$F$2:$F$223,"Software & IT Subscriptions")-SUMIFS('2026 Bank Transactions'!$E$2:$E$223,'2026 Bank Transactions'!$A$2:$A$223,"May/Jun 2026",'2026 Bank Transactions'!$F$2:$F$223,"Software & IT Subscriptions") -> -3091.27 | F20: =SUMIFS('2026 Bank Transactions'!$D$2:$D$223,'2026 Bank Transactions'!$A$2:$A$223,"Jul/Aug 2026",'2026 Bank Transactions'!$F$2:$F$223,"Software & IT Subscriptions")-SUMIFS('2026 Bank Transactions'!$E$2:$E$223,'2026 Bank Transactions'!$A$2:$A$223,"Jul/Aug 2026",'2026 Bank Transactions'!$F$2:$F$223,"Software & IT Subscriptions") -> -521.88 | G20: =SUM(C20:F20) -> -8748.64
B21: Insurance | C21: =SUMIFS('2026 Bank Transactions'!$D$2:$D$223,'2026 Bank Transactions'!$A$2:$A$223,"Jan/Feb 2026",'2026 Bank Transactions'!$F$2:$F$223,"Insurance")-SUMIFS('2026 Bank Transactions'!$E$2:$E$223,'2026 Bank Transactions'!$A$2:$A$223,"Jan/Feb 2026",'2026 Bank Transactions'!$F$2:$F$223,"Insurance") -> -1350 | D21: =SUMIFS('2026 Bank Transactions'!$D$2:$D$223,'2026 Bank Transactions'!$A$2:$A$223,"Mar/Apr 2026",'2026 Bank Transactions'!$F$2:$F$223,"Insurance")-SUMIFS('2026 Bank Transactions'!$E$2:$E$223,'2026 Bank Transactions'!$A$2:$A$223,"Mar/Apr 2026",'2026 Bank Transactions'!$F$2:$F$223,"Insurance") -> -38500 | E21: =SUMIFS('2026 Bank Transactions'!$D$2:$D$223,'2026 Bank Transactions'!$A$2:$A$223,"May/Jun 2026",'2026 Bank Transactions'!$F$2:$F$223,"Insurance")-SUMIFS('2026 Bank Transactions'!$E$2:$E$223,'2026 Bank Transactions'!$A$2:$A$223,"May/Jun 2026",'2026 Bank Transactions'!$F$2:$F$223,"Insurance") -> -5089.13 | F21: =SUMIFS('2026 Bank Transactions'!$D$2:$D$223,'2026 Bank Transactions'!$A$2:$A$223,"Jul/Aug 2026",'2026 Bank Transactions'!$F$2:$F$223,"Insurance")-SUMIFS('2026 Bank Transactions'!$E$2:$E$223,'2026 Bank Transactions'!$A$2:$A$223,"Jul/Aug 2026",'2026 Bank Transactions'!$F$2:$F$223,"Insurance") -> -7500 | G21: =SUM(C21:F21) -> -52439.13
B22: Payroll & Directors' Remuneration | C22: =SUMIFS('2026 Bank Transactions'!$D$2:$D$223,'2026 Bank Transactions'!$A$2:$A$223,"Jan/Feb 2026",'2026 Bank Transactions'!$F$2:$F$223,"Payroll & Directors' Remuneration")-SUMIFS('2026 Bank Transactions'!$E$2:$E$223,'2026 Bank Transactions'!$A$2:$A$223,"Jan/Feb 2026",'2026 Bank Transactions'!$F$2:$F$223,"Payroll & Directors' Remuneration") -> -17129.34 | D22: =SUMIFS('2026 Bank Transactions'!$D$2:$D$223,'2026 Bank Transactions'!$A$2:$A$223,"Mar/Apr 2026",'2026 Bank Transactions'!$F$2:$F$223,"Payroll & Directors' Remuneration")-SUMIFS('2026 Bank Transactions'!$E$2:$E$223,'2026 Bank Transactions'!$A$2:$A$223,"Mar/Apr 2026",'2026 Bank Transactions'!$F$2:$F$223,"Payroll & Directors' Remuneration") -> -17492.47 | E22: =SUMIFS('2026 Bank Transactions'!$D$2:$D$223,'2026 Bank Transactions'!$A$2:$A$223,"May/Jun 2026",'2026 Bank Transactions'!$F$2:$F$223,"Payroll & Directors' Remuneration")-SUMIFS('2026 Bank Transactions'!$E$2:$E$223,'2026 Bank Transactions'!$A$2:$A$223,"May/Jun 2026",'2026 Bank Transactions'!$F$2:$F$223,"Payroll & Directors' Remuneration") -> -8181.99 | F22: =SUMIFS('2026 Bank Transactions'!$D$2:$D$223,'2026 Bank Transactions'!$A$2:$A$223,"Jul/Aug 2026",'2026 Bank Transactions'!$F$2:$F$223,"Payroll & Directors' Remuneration")-SUMIFS('2026 Bank Transactions'!$E$2:$E$223,'2026 Bank Transactions'!$A$2:$A$223,"Jul/Aug 2026",'2026 Bank Transactions'!$F$2:$F$223,"Payroll & Directors' Remuneration") -> 0 | G22: =SUM(C22:F22) -> -42803.8
B23: Professional & Statutory Fees | C23: =SUMIFS('2026 Bank Transactions'!$D$2:$D$223,'2026 Bank Transactions'!$A$2:$A$223,"Jan/Feb 2026",'2026 Bank Transactions'!$F$2:$F$223,"Professional & Statutory Fees")-SUMIFS('2026 Bank Transactions'!$E$2:$E$223,'2026 Bank Transactions'!$A$2:$A$223,"Jan/Feb 2026",'2026 Bank Transactions'!$F$2:$F$223,"Professional & Statutory Fees") -> 0 | D23: =SUMIFS('2026 Bank Transactions'!$D$2:$D$223,'2026 Bank Transactions'!$A$2:$A$223,"Mar/Apr 2026",'2026 Bank Transactions'!$F$2:$F$223,"Professional & Statutory Fees")-SUMIFS('2026 Bank Transactions'!$E$2:$E$223,'2026 Bank Transactions'!$A$2:$A$223,"Mar/Apr 2026",'2026 Bank Transactions'!$F$2:$F$223,"Professional & Statutory Fees") -> -4390 | E23: =SUMIFS('2026 Bank Transactions'!$D$2:$D$223,'2026 Bank Transactions'!$A$2:$A$223,"May/Jun 2026",'2026 Bank Transactions'!$F$2:$F$223,"Professional & Statutory Fees")-SUMIFS('2026 Bank Transactions'!$E$2:$E$223,'2026 Bank Transactions'!$A$2:$A$223,"May/Jun 2026",'2026 Bank Transactions'!$F$2:$F$223,"Professional & Statutory Fees") -> 0 | F23: =SUMIFS('2026 Bank Transactions'!$D$2:$D$223,'2026 Bank Transactions'!$A$2:$A$223,"Jul/Aug 2026",'2026 Bank Transactions'!$F$2:$F$223,"Professional & Statutory Fees")-SUMIFS('2026 Bank Transactions'!$E$2:$E$223,'2026 Bank Transactions'!$A$2:$A$223,"Jul/Aug 2026",'2026 Bank Transactions'!$F$2:$F$223,"Professional & Statutory Fees") -> -20 | G23: =SUM(C23:F23) -> -4410
B24: Travel, Subsistence & Entertainment | C24: =SUMIFS('2026 Bank Transactions'!$D$2:$D$223,'2026 Bank Transactions'!$A$2:$A$223,"Jan/Feb 2026",'2026 Bank Transactions'!$F$2:$F$223,"Travel, Subsistence & Entertainment")-SUMIFS('2026 Bank Transactions'!$E$2:$E$223,'2026 Bank Transactions'!$A$2:$A$223,"Jan/Feb 2026",'2026 Bank Transactions'!$F$2:$F$223,"Travel, Subsistence & Entertainment") -> -793.49 | D24: =SUMIFS('2026 Bank Transactions'!$D$2:$D$223,'2026 Bank Transactions'!$A$2:$A$223,"Mar/Apr 2026",'2026 Bank Transactions'!$F$2:$F$223,"Travel, Subsistence & Entertainment")-SUMIFS('2026 Bank Transactions'!$E$2:$E$223,'2026 Bank Transactions'!$A$2:$A$223,"Mar/Apr 2026",'2026 Bank Transactions'!$F$2:$F$223,"Travel, Subsistence & Entertainment") -> -343.46 | E24: =SUMIFS('2026 Bank Transactions'!$D$2:$D$223,'2026 Bank Transactions'!$A$2:$A$223,"May/Jun 2026",'2026 Bank Transactions'!$F$2:$F$223,"Travel, Subsistence & Entertainment")-SUMIFS('2026 Bank Transactions'!$E$2:$E$223,'2026 Bank Transactions'!$A$2:$A$223,"May/Jun 2026",'2026 Bank Transactions'!$F$2:$F$223,"Travel, Subsistence & Entertainment") -> -3274.86 | F24: =SUMIFS('2026 Bank Transactions'!$D$2:$D$223,'2026 Bank Transactions'!$A$2:$A$223,"Jul/Aug 2026",'2026 Bank Transactions'!$F$2:$F$223,"Travel, Subsistence & Entertainment")-SUMIFS('2026 Bank Transactions'!$E$2:$E$223,'2026 Bank Transactions'!$A$2:$A$223,"Jul/Aug 2026",'2026 Bank Transactions'!$F$2:$F$223,"Travel, Subsistence & Entertainment") -> -639.01 | G24: =SUM(C24:F24) -> -5050.82
B25: Tax Payments (Revenue Commissioners) | C25: =SUMIFS('2026 Bank Transactions'!$D$2:$D$223,'2026 Bank Transactions'!$A$2:$A$223,"Jan/Feb 2026",'2026 Bank Transactions'!$F$2:$F$223,"Tax Payments (Revenue Commissioners)")-SUMIFS('2026 Bank Transactions'!$E$2:$E$223,'2026 Bank Transactions'!$A$2:$A$223,"Jan/Feb 2026",'2026 Bank Transactions'!$F$2:$F$223,"Tax Payments (Revenue Commissioners)") -> -16168.94 | D25: =SUMIFS('2026 Bank Transactions'!$D$2:$D$223,'2026 Bank Transactions'!$A$2:$A$223,"Mar/Apr 2026",'2026 Bank Transactions'!$F$2:$F$223,"Tax Payments (Revenue Commissioners)")-SUMIFS('2026 Bank Transactions'!$E$2:$E$223,'2026 Bank Transactions'!$A$2:$A$223,"Mar/Apr 2026",'2026 Bank Transactions'!$F$2:$F$223,"Tax Payments (Revenue Commissioners)") -> -1361.75 | E25: =SUMIFS('2026 Bank Transactions'!$D$2:$D$223,'2026 Bank Transactions'!$A$2:$A$223,"May/Jun 2026",'2026 Bank Transactions'!$F$2:$F$223,"Tax Payments (Revenue Commissioners)")-SUMIFS('2026 Bank Transactions'!$E$2:$E$223,'2026 Bank Transactions'!$A$2:$A$223,"May/Jun 2026",'2026 Bank Transactions'!$F$2:$F$223,"Tax Payments (Revenue Commissioners)") -> -3580.87 | F25: =SUMIFS('2026 Bank Transactions'!$D$2:$D$223,'2026 Bank Transactions'!$A$2:$A$223,"Jul/Aug 2026",'2026 Bank Transactions'!$F$2:$F$223,"Tax Payments (Revenue Commissioners)")-SUMIFS('2026 Bank Transactions'!$E$2:$E$223,'2026 Bank Transactions'!$A$2:$A$223,"Jul/Aug 2026",'2026 Bank Transactions'!$F$2:$F$223,"Tax Payments (Revenue Commissioners)") -> -6341.35 | G25: =SUM(C25:F25) -> -27452.91
B26: Bank, Card & Misc Fees | C26: =SUMIFS('2026 Bank Transactions'!$D$2:$D$223,'2026 Bank Transactions'!$A$2:$A$223,"Jan/Feb 2026",'2026 Bank Transactions'!$F$2:$F$223,"Bank, Card & Misc Fees")-SUMIFS('2026 Bank Transactions'!$E$2:$E$223,'2026 Bank Transactions'!$A$2:$A$223,"Jan/Feb 2026",'2026 Bank Transactions'!$F$2:$F$223,"Bank, Card & Misc Fees") -> -1931.2 | D26: =SUMIFS('2026 Bank Transactions'!$D$2:$D$223,'2026 Bank Transactions'!$A$2:$A$223,"Mar/Apr 2026",'2026 Bank Transactions'!$F$2:$F$223,"Bank, Card & Misc Fees")-SUMIFS('2026 Bank Transactions'!$E$2:$E$223,'2026 Bank Transactions'!$A$2:$A$223,"Mar/Apr 2026",'2026 Bank Transactions'!$F$2:$F$223,"Bank, Card & Misc Fees") -> -2020.65 | E26: =SUMIFS('2026 Bank Transactions'!$D$2:$D$223,'2026 Bank Transactions'!$A$2:$A$223,"May/Jun 2026",'2026 Bank Transactions'!$F$2:$F$223,"Bank, Card & Misc Fees")-SUMIFS('2026 Bank Transactions'!$E$2:$E$223,'2026 Bank Transactions'!$A$2:$A$223,"May/Jun 2026",'2026 Bank Transactions'!$F$2:$F$223,"Bank, Card & Misc Fees") -> -1433.4 | F26: =SUMIFS('2026 Bank Transactions'!$D$2:$D$223,'2026 Bank Transactions'!$A$2:$A$223,"Jul/Aug 2026",'2026 Bank Transactions'!$F$2:$F$223,"Bank, Card & Misc Fees")-SUMIFS('2026 Bank Transactions'!$E$2:$E$223,'2026 Bank Transactions'!$A$2:$A$223,"Jul/Aug 2026",'2026 Bank Transactions'!$F$2:$F$223,"Bank, Card & Misc Fees") -> -560.88 | G26: =SUM(C26:F26) -> -5946.13
B27: Unlabeled / Uncategorised Items | C27: =SUMIFS('2026 Bank Transactions'!$D$2:$D$223,'2026 Bank Transactions'!$A$2:$A$223,"Jan/Feb 2026",'2026 Bank Transactions'!$F$2:$F$223,"Unlabeled / Uncategorised Item")-SUMIFS('2026 Bank Transactions'!$E$2:$E$223,'2026 Bank Transactions'!$A$2:$A$223,"Jan/Feb 2026",'2026 Bank Transactions'!$F$2:$F$223,"Unlabeled / Uncategorised Item") -> 0 | D27: =SUMIFS('2026 Bank Transactions'!$D$2:$D$223,'2026 Bank Transactions'!$A$2:$A$223,"Mar/Apr 2026",'2026 Bank Transactions'!$F$2:$F$223,"Unlabeled / Uncategorised Item")-SUMIFS('2026 Bank Transactions'!$E$2:$E$223,'2026 Bank Transactions'!$A$2:$A$223,"Mar/Apr 2026",'2026 Bank Transactions'!$F$2:$F$223,"Unlabeled / Uncategorised Item") -> 0 | E27: =SUMIFS('2026 Bank Transactions'!$D$2:$D$223,'2026 Bank Transactions'!$A$2:$A$223,"May/Jun 2026",'2026 Bank Transactions'!$F$2:$F$223,"Unlabeled / Uncategorised Item")-SUMIFS('2026 Bank Transactions'!$E$2:$E$223,'2026 Bank Transactions'!$A$2:$A$223,"May/Jun 2026",'2026 Bank Transactions'!$F$2:$F$223,"Unlabeled / Uncategorised Item") -> 0 | F27: =SUMIFS('2026 Bank Transactions'!$D$2:$D$223,'2026 Bank Transactions'!$A$2:$A$223,"Jul/Aug 2026",'2026 Bank Transactions'!$F$2:$F$223,"Unlabeled / Uncategorised Item")-SUMIFS('2026 Bank Transactions'!$E$2:$E$223,'2026 Bank Transactions'!$A$2:$A$223,"Jul/Aug 2026",'2026 Bank Transactions'!$F$2:$F$223,"Unlabeled / Uncategorised Item") -> 1341.07 | G27: =SUM(C27:F27) -> 1341.07
B28: Total Operating Expenses | C28: =SUM(C20:C27) -> -41996.54 | D28: =SUM(D20:D27) -> -64620.25 | E28: =SUM(E20:E27) -> -24651.52 | F28: =SUM(F20:F27) -> -14242.05 | G28: =SUM(C28:F28) -> -145510.36
B31: NET PROFIT / (LOSS) | C31: =C17+C28 -> -45496.17 | D31: =D17+D28 -> -43997 | E31: =E17+E28 -> 2383.63 | F31: =F17+F28 -> 52333.85 | G31: =SUM(C31:F31) -> -34775.69

Sheet 2026 Bank Transactions
A1: Period | B1: Bank Records Row | C1: Vendor / Description | D1: In (EUR) | E1: Out (EUR) | F1: P&L Category
A2: Jan/Feb 2026 | B2: 4 | C2: GOOGLE WORKSPACE | E2: 9.96 | F2: Software & IT Subscriptions
A3: Jan/Feb 2026 | B3: 5 | C3: CLEVERCARDS | E3: 3133.8 | F3: Software & IT Subscriptions
A4: Jan/Feb 2026 | B4: 6 | C4: 512121000234402026 SP | D4: 3678.93 | F4: Sales Revenue
A5: Jan/Feb 2026 | B5: 7 | C5: INSIGHT | E5: 246 | F5: Software & IT Subscriptions
A6: Jan/Feb 2026 | B6: 8 | C6: POS06JAN SAS | E6: 50 | F6: Bank, Card & Misc Fees
A7: Jan/Feb 2026 | B7: 9 | C7: POS06JAN SAS | E7: 529.56 | F7: Bank, Card & Misc Fees
A8: Jan/Feb 2026 | B8: 10 | C8: POS06JAN SAS | E8: 529.56 | F8: Bank, Card & Misc Fees
A9: Jan/Feb 2026 | B9: 11 | C9: POS06JAN SAS | E9: 529.56 | F9: Bank, Card & Misc Fees
A10: Jan/Feb 2026 | B10: 12 | C10: POS09JAN PAYPAL PPGF | E10: 1 | F10: Bank, Card & Misc Fees
A11: Jan/Feb 2026 | B11: 13 | C11: ALI EXPRESS | E11: 83.04 | F11: Materials & Components
A12: Jan/Feb 2026 | B12: 14 | C12: SCREWFIX | E12: 88.65 | F12: Materials & Components
A13: Jan/Feb 2026 | B13: 15 | C13: ARACHAS.IE O | E13: 1350 | F13: Insurance
A14: Jan/Feb 2026 | B14: 16 | C14: EATM | E14: 94.5 | F14: Travel, Subsistence & Entertainment
A15: Jan/Feb 2026 | B15: 17 | C15: BARRIE | E15: 166.43 | F15: Travel, Subsistence & Entertainment
A16: Jan/Feb 2026 | B16: 18 | C16: RUBIX | D16: 1353 | F16: Sales Revenue
A17: Jan/Feb 2026 | B17: 19 | C17: APPLE.COM | E17: 1038 | F17: Materials & Components
A18: Jan/Feb 2026 | B18: 20 | C18: URBAN K | E18: 29.7 | F18: Travel, Subsistence & Entertainment
A19: Jan/Feb 2026 | B19: 21 | C19: PPGF | E19: 1 | F19: Bank, Card & Misc Fees
A20: Jan/Feb 2026 | B20: 22 | C20: BAMB | E20: 236.5 | F20: Automation Subcontractors & Suppliers
A21: Jan/Feb 2026 | B21: 23 | C21: REVENUE | E21: 14367 | F21: Tax Payments (Revenue Commissioners)
A22: Jan/Feb 2026 | B22: 24 | C22: REVENUE | E22: 1121.07 | F22: Tax Payments (Revenue Commissioners)
A23: Jan/Feb 2026 | B23: 25 | C23: ALI EXPRESS | E23: 32.53 | F23: Materials & Components
A24: Jan/Feb 2026 | B24: 26 | C24: TITAN CONTAI | E24: 2626.36 | F24: Automation Subcontractors & Suppliers
A25: Jan/Feb 2026 | B25: 27 | C25: SCREWFIX | E25: 16.7 | F25: Materials & Components
A26: Jan/Feb 2026 | B26: 28 | C26: INSIGHT | E26: 246 | F26: Software & IT Subscriptions
A27: Jan/Feb 2026 | B27: 29 | C27: ATC | E27: 1734.69 | F27: Automation Subcontractors & Suppliers
A28: Jan/Feb 2026 | B28: 30 | C28: GOOGLE WORKSPACE | E28: 9.96 | F28: Software & IT Subscriptions
... A49: Jan/Feb 2026 | B49: 51 | C49: PAYPAL BOOK | E49: 157 | F49: Bank, Card & Misc Fees
A50: Mar/Apr 2026 | B50: 4 | C50: MDI | D50: 1000 | F50: Sales Revenue
A51: Mar/Apr 2026 | B51: 5 | C51: PAYPAL BOOK | E51: 137 | F51: Bank, Card & Misc Fees
A52: Mar/Apr 2026 | B52: 6 | C52: GOOGLE WORKSPACE | E52: 9.96 | F52: Software & IT Subscriptions
A53: Mar/Apr 2026 | B53: 7 | C53: MDI | D53: 845 | F53: Sales Revenue
A54: Mar/Apr 2026 | B54: 8 | C54: NATIONAL AUTO SPEA DD | E54: 51 | F54: Bank, Card & Misc Fees
A55: Mar/Apr 2026 | B55: 9 | C55: ABGI | E55: 3690 | F55: Professional & Statutory Fees
A56: Mar/Apr 2026 | B56: 10 | C56: N2 ELECTRICAL | E56: 724.97 | F56: Automation Subcontractors & Suppliers
A57: Mar/Apr 2026 | B57: 11 | C57: BAMBU | E57: 241.09 | F57: Automation Subcontractors & Suppliers
A58: Mar/Apr 2026 | B58: 12 | C58: ORAL B | E58: 0.65 | F58: Bank, Card & Misc Fees
A59: Mar/Apr 2026 | B59: 13 | C59: MICHAEL FARRELLY | E59: 1599.28 | F59: Payroll & Directors' Remuneration
A60: Mar/Apr 2026 | B60: 14 | C60: MICHAEL FARRELLY | E60: 1 | F60: Payroll & Directors' Remuneration
...

Sheet BANK RECORDS
C2: JAN/FEB | I2: MAR/APR | N2: MAY/JUNE | T2: JULY/AUG | Z2: SEP/OCT | AF2: NOV/DEC | AL2: JAN/FEB | AR2: MAR/APR | AX2: MAY/JUN | BD2: JUL/AUG
C3: vendor | D3: in | E3: out | F3: total | I3: vendor | J3: in | K3: out | L3: total | O3: vendor | P3: in | Q3: out | R3: total | U3: vendor | V3: in | W3: out | X3: total | AA3: vendor | AB3: in | AC3: out | AD3: total | AG3: vendor | AH3: in | AI3: out | AJ3: total | AM3: vendor | AN3: in | AO3: out | AP3: total | AS3: vendor | AT3: in | AU3: out | AV3: total | AY3: vendor | AZ3: in | BA3: out | BB3: total | BE3: vendor | BF3: in | BG3: out | BH3: total
C4: transfer des | D4: 10 | F4: 10 | I4: googlegsuit | K4: 7.82 | L4: 15002.57 | O4: gsuit | Q4: 9.96 | R4: 21756.64 | U4: DAVE EGAN | W4: 3230 | X4: 49554.89 | AA4: SIXT | AC4: 13.36 | AD4: 60631.22 | AG4: GOOGLE WORKSPACE | AI4: 9.96 | AJ4: 75327.63 | AM4: GOOGLE WORKSPACE | AO4: 9.96 | AP4: 104912.02 | AS4: MDI | AT4: 1000 | AV4: 60425.81 | AY4: TESCO | BA4: 200 | BB4: 15228.81 | BE4: Irish Life SEPA DD | BG4: 1250 | BH4: 16562.44
C5: transfer des | D5: 14760 | F5: 14770 | I5: paypal unit | K5: 150.35 | L5: 14852.22 | O5: mcdonalds | Q5: 12.1 | R5: 21744.54 | U5: GSUIT | W5: 9.96 | X5: 49544.93 | AA5: EXPERT BE | AC5: 233.36 | AD5: 60397.86 | AG5: INSIGHT ACCOUNT IP | AI5: 246 | AJ5: 75081.63 | AM5: CLEVERCARDS | AO5: 3133.8 | AP5: 101778.22 | AS5: PAYPAL BOOK | AU5: 137 | AV5: 60288.81 | AY5: TESCO | BA5: 200 | BB5: 15028.81 | BE5: AVIVA L + P SEPA DD | BG5: 1250 | BH5: 15312.44
C6: online 21149402 | E6: 1476 | F6: 13294 | I6: temu | K6: 52.63 | L6: 14799.59 | O6: savoury | Q6: 20.25 | R6: 21724.29 | U6: HENKEL | V6: 21771.55 | X6: 71316.48 | AA6: GSUIT | AC6: 9.96 | AD6: 60387.9 | AG6: ATC | AI6: 590.49 | AJ6: 74491.14 | AM6: 512121000234402026 SP | AN6: 3678.93 | AP6: 105457.15 | AS6: GOOGLE WORKSPACE | AU6: 9.96 | AV6: 60278.85 | AY6: TESCO | BA6: 200 | BB6: 14828.81 | BE6: National Auto SEPA DD | BG6: 48 | BH6: 15264.44
C7: 365 insight | E7: 1000 | F7: 12294 | I7: temu | K7: 4.63 | L7: 14794.96 | O7: DC AUTOMATION | Q7: 1077.97 | R7: 20646.32 | U7: BPX | W7: 5537.15 | X7: 65779.33 | AA7: ROBOTUNI | AC7: 248.28 | AD7: 60139.62 | AG7: 515151 | AH7: 49999.87 | AJ7: 124491.01 | AM7: INSIGHT | AO7: 246 | AP7: 105211.15 | AS7: MDI | AT7: 845 | AV7: 61123.85 | AY7: TESCO | BA7: 200 | BB7: 14628.81 | BE7: google works | BG7: 9.96 | BH7: 15254.48
C8: 365 insight | E8: 350 | F8: 11944 | I8: demense elec | K8: 227.85 | L8: 14567.11 | O8: DC AUTOMATION | Q8: 651.9 | R8: 19994.42 | U8: FLYNN SIGNS | W8: 325.79 | X8: 65453.54 | AA8: CIRCLE K | AC8: 114.65 | AD8: 60024.97 | AG8: BAMBU LAB | AI8: 1826.29 | AJ8: 122664.72 | AM8: POS06JAN SAS | AO8: 50 | AP8: 105161.15 | AS8: NATIONAL AUTO SPEA DD | AU8: 51 | AV8: 61072.85 | AY8: TESCO | BA8: 200 | BB8: 14428.81 | BE8: machine buil | BG8: 134.39 | BH8: 15120.09
C9: L limited | D9: 25092 | F9: 37036 | I9: BPX elect | K9: 201.63 | L9: 14365.48 | O9: paypal temu | Q9: 27.07 | R9: 19967.35 | U9: LIDL | W9: 31.46 | X9: 65422.08 | AA9: SIXT | AC9: 416.29 | AD9: 59608.68 | AG9: HOME APPLIANCE | AI9: 379.99 | AJ9: 122284.73 | AM9: POS06JAN SAS | AO9: 529.56 | AP9: 104631.59 | AS9: ABGI | AU9: 3690 | AV9: 57382.85 | AY9: TESCO | BA9: 200 | BB9: 14228.81 | BE9: bambu lab | BG9: 526.54 | BH9: 14593.55
C10: 365 online 21149402 | E10: 2040 | F10: 34996 | I10: sequence | K10: 3444 | L10: 10921.48 | O10: paypal temu | Q10: 3.72 | R10: 19963.63 | U10: TEMU | W10: 56.89 | X10: 65365.19 | AA10: TRAN FARRELLY | AC10: 10 | AD10: 59598.68 | AG10: SAVOURY | AI10: 24.5 | AJ10: 122260.23 | AM10: POS06JAN SAS | AO10: 529.56 | AP10: 104102.03 | AS10: N2 ELECTRICAL | AU10: 724.97 | AV10: 56657.88 | AY10: TESCO | BA10: 200 | BB10: 14028.81 | BE10: baldoyle ski | BG10: 360 | BH10: 14233.55
C11: revenue sepa | E11: 2760 | F11: 32236 | I11: marwan fa gp | J11: 16819.92 | L11: 27741.4 | O11: paypal temu | Q11: 7.96 | R11: 19955.67 | U11: N2 ELECTRICA | W11: 279.71 | X11: 65085.48 | AA11: TRAN MICHAEL | AC11: 10 | AD11: 59588.68 | AG11: TEMU | AI11: 111.78 | AJ11: 122148.45 | AM11: POS06JAN SAS | AO11: 529.56 | AP11: 103572.47 | AS11: BAMBU | AU11: 241.09 | AV11: 56416.79 | AY11: TESCO | BA11: 200 | BB11: 13828.81 | BE11: hodson bay | BG11: 38.95 | BH11: 14194.6
B12: FEB | C12: Machine buill | D12: 40.59 | F12: 32276.59 | I12: marwan | K12: 12.5 | L12: 27728.9 | O12: paypal temu | Q12: 8.06 | R12: 19947.61 | U12: N2 ELECTRICA | W12: 116.85 | X12: 64968.63 | AA12: LIDL | AC12: 22.28 | AD12: 59566.4 | AG12: EBAY | AI12: 20.89 | AJ12: 122127.56 | AM12: POS09JAN PAYPAL PPGF | AO12: 1 | AP12: 103571.47 | AS12: ORAL B | AU12: 0.65 | AV12: 56416.14 | AY12: TESCO | BA12: 200 | BB12: 13628.81 | BE12: paypal book | BG12: 154 | BH12: 14040.6
C13: Machine buill | E13: 332.08 | F13: 31944.51 | I13: paypal alip | K13: 105.03 | L13: 27623.87 | O13: paypal temu | Q13: 36.6 | R13: 19911.01 | U13: DC AUTOMATION | W13: 2472.3 | X13: 62496.33 | AA13: DEMESNE ELEC | AC13: 320.96 | AD13: 59245.44 | AG13: EBAY | AI13: 9.82 | AJ13: 122117.74 | AM13: ALI EXPRESS | AO13: 83.04 | AP13: 103488.43 | AS13: MICHAEL FARRELLY | AU13: 1599.28 | AV13: 54816.86 | AY13: TESCO | BA13: 200 | BB13: 13428.81 | BE13: companies re | BG13: 20 | BH13: 14020.6
C14: paypal bell | E14: 359.13 | F14: 31585.38 | I14: ntron | K14: 1110 | L14: 26513.87 | O14: paypal temu | Q14: 5.74 | R14: 19905.27 | U14: NTRON LIM | W14: 1432.95 | X14: 61063.38 | AA14: GRANGE BUIL | AC14: 28.04 | AD14: 59217.4 | AG14: CREA (MICKS GARAGE) | AI14: 29.94 | AJ14: 122087.8 | AM14: SCREWFIX | AO14: 88.65 | AP14: 103399.78 | AS14: MICHAEL FARRELLY | AU14: 1 | AV14: 54815.86 | AY14: TESCO | BA14: 200 | BB14: 13228.81 | BE14: eflow | BG14: 53.23 | BH14: 13967.37
C15: flowcon | E15: 2316.09 | F15: 29269.29 | I15: the dublin p | K15: 463.71 | L15: 26050.16 | O15: DC AUTOMATION | Q15: 1355.46 | R15: 18549.81 | U15: HYDRAQUIP | W15: 2156.19 | X15: 58907.19 | AA15: SCREWFIX | AC15: 100.9 | AD15: 59116.5 | AG15: ALS | AH15: 615 | AJ15: 122702.8 | AM15: ARACHAS.IE O | AO15: 1350 | AP15: 102049.78 | AS15: DES FARRELLY | AU15: 2546.34 | AV15: 52269.52 | AY15: TESCO | BA15: 200 | BB15: 13028.81 | BE15: insight | BG15: 246 | BH15: 13721.37
C16: IFM elec | E16: 1099.2 | F16: 28170.09 | I16: 21149402 | K16: 1681 | L16: 24369.16 | O16: Paypal bamb | Q16: 140.41 | R16: 18409.4 | U16: IFM ELECT | W16: 1178.91 | X16: 57728.28 | AA16: TOM CAMPB | AC16: 4920 | AD16: 54196.5 | AG16: BAMBU LAB | AI16: 90.07 | AJ16: 122612.73 | AM16: EATM | AO16: 94.5 | AP16: 101955.28 | AS16: DF269 DF273 DF266 | AT16: 22145.54 | AV16: 74415.06 | AY16: TESCO | BA16: 200 | BB16: 12828.81 | BE16: dc automated | BG16: 563.34 | BH16: 13158.03
C17: watson m | E17: 3125.92 | F17: 25044.17 | I17: ntron | K17: 322.95 | L17: 24046.21 | O17: demense ele | Q17: 17.17 | R17: 18392.23 | U17: BIBUS UK | W17: 475.04 | X17: 57253.24 | AA17: LIDL | AC17: 17.98 | AD17: 54178.52 | AG17: EFLOW | AI17: 112.63 | AJ17: 122500.1 | AM17: BARRIE | AO17: 166.43 | AP17: 101788.85 | AS17: PAYPAL PPGF | AU17: 1 | AV17: 74414.06 | AY17: TESCO | BA17: 200 | BB17: 12628.81 | BE17: revenue commi SEPA DD | BG17: 5070 | BH17: 8088.03
C18: bpx elect | E18: 5421.25 | F18: 19622.92 | I18: tom camp | K18: 335 | L18: 23711.21 | O18: hygiene solu | Q18: 60 | R18: 18332.23 | U18: BELLINGHAM C | W18: 225 | X18: 57028.24 | AA18: PAYPAL CRIS | AC18: 83.7 | AD18: 54094.82 | AG18: SIXT | AH18: 22.27 | AJ18: 122522.37 | AM18: RUBIX | AN18: 1353 | AP18: 103141.85 | AS18: ALI EXPRESS | AU18: 148.95 | AV18: 74265.11 | AY18: TESCO | BA18: 200 | BB18: 12428.81 | BE18: paypal book | BG18: 100.8 | BH18: 7987.23
C19: M limited 25021 SP | D19: 123 | F19: 19745.92 | I19: paypal tran mar20 | K19: 99.72 | L19: 23611.49 | O19: IFM ELECT | Q19: 101.23 | R19: 18231 | U19: PAYPAL BELL | W19: 346.61 | X19: 56681.63 | AA19: TRAN MICHAEL | AC19: 3816 | AD19: 50278.82 | AG19: HYGIENE SOLUTIONS | AI19: 60 | AJ19: 122462.37 | AM19: APPLE.COM | AO19: 1038 | AP19: 102103.85 | AS19: EFLOW | AU19: 235.03 | AV19: 74030.08 | AY19: 512121000242312026 SP | AZ19: 11404.56 | BB19: 23833.37 | BE19: revenue commi SEPA DD | BG19: 629.01 | BH19: 7358.22
C20: ATC | E20: 187.15 | F20: 19558.77 | I20: temu | K20: 3.13 | L20: 23608.36 | O20: Insight | Q20: 246 | R20: 17985 | U20: PAYPAL BAMB | W20: 397.31 | X20: 56284.32 | AA20: M LIMITED 25091 SP (DF211) | AB20: 3136.5 | AD20: 53415.32 | AG20: BAMBU LAB | AI20: 212.24 | AJ20: 122250.13 | AM20: URBAN K | AO20: 29.7 | AP20: 102074.15 | AS20: BAMBU | AU20: 176.79 | AV20: 73853.29 | AY20: screw fix | BA20: 42.55 | BB20: 23790.82 | BE20: ecoplex | BG20: 1230 | BH20: 6128.22
C21: Bibus | E21: 510.36 | F21: 19048.41 | I21: temu | K21: 1.85 | L21: 23606.51 | O21: Insight | Q21: 615 | R21: 17370 | U21: HYRAQUIP | W21: 220.17 | X21: 56064.15 | AA21: EFLOW | AC21: 1.23 | AD21: 53414.09 | AG21: REVEUNUE COMMI | AI21: 6554 | AJ21: 115696.13 | AM21: PPGF | AO21: 1 | AP21: 102073.15 | AS21: DF238/DF259 | AT21: 3136.5 | AV21: 76989.79 | AY21: irish life sepa | BA21: 1250 | BB21: 22540.82 | BE21: radionics | BG21: 36.32 | BH21: 6091.9
C22: hydraquip | E22: 1444.02 | F22: 17604.39 | I22: temu | K22: 70.26 | L22: 23536.25 | O22: Insight | Q22: 246 | R22: 17124 | U22: WATSON M | W22: 3125.92 | X22: 52938.23 | AA22: IRRITEC LTD | AC22: 50.36 | AD22: 53363.73 | AG22: REVEUNUE COMMI | AI22: 1105.94 | AJ22: 114590.19 | AM22: BAMB | AO22: 236.5 | AP22: 101836.65 | AS22: REVVAT | AT22: 886 | AV22: 77875.79 | AY22: Aviva L + P SEPA DD | BA22: 1250 | BB22: 21290.82 | BE22: m limited 26073 sp | BF22: 35590.05 | BH22: 41681.95
C23: ATC | E23: 1877.26 | F23: 15727.13 | I23: 19mar paypal alip | K23: 481.11 | L23: 23055.14 | O23: misumi | Q23: 466.5 | R23: 16657.5 | U23: CLU | W23: 25 | X23: 52913.23 | AA23: N2 | AC23: 277.12 | AD23: 53086.61 | AF23: DEC | AG23: INSIGHT ACCOUNT IP | AI23: 246 | AJ23: 114344.19 | AM23: REVENUE | AO23: 14367 | AP23: 87469.65 | AQ23: 15488.07 | AS23: REVENUE COMMI | AU23: 680.88 | AV23: 77194.91 | AY23: google | BA23: 9.96 | BB23: 21280.86 | BE23: ebay | BG23: 249.66 | BH23: 41432.29
C24: savoury | E24: 55.25 | F24: 15671.88 | I24: rev commi sepa | K24: 1954 | L24: 21101.14 | O24: Paypal bamb | Q24: 103.2 | R24: 16554.3 | U24: PAYPAL UNIT | W24: 156.4 | X24: 52756.83 | AA24: N2 | AC24: 195.29 | AD24: 52891.32 | AG24: MICHAEL WAGES | AI24: 3782.15 | AJ24: 110562.04 | AM24: REVENUE | AO24: 1121.07 | AP24: 86348.58 | AV24: 77194.91 | AY24: National Auto Sepa DD | BA24: 51 | BB24: 21229.86 | BE24: ebay | BG24: 187.54 | BH24: 41244.75
C25: paypal parc | E25: 94.35 | F25: 15577.53 | I25: 27mar paypal alip | K25: 16.86 | L25: 21084.28 | O25: radionics | Q25: 14.24 | R25: 16540.06 | U25: HARVEY NORMA | W25: 560.9 | X25: 52195.93 | AA25: DCU FEES | AC25: 6960 | AD25: 45931.32 | AG25: MICHAEL WAGES | AI25: 3782.15 | AJ25: 106779.89 | AM25: ALI EXPRESS | AO25: 32.53 | AP25: 86316.05 | AS25: INSIGHT | AU25: 246 | AV25: 76948.91 | AY25: Demence | BA25: 62.26 | BB25: 21167.6 | BE25: Irish Life SEPA DD | BG25: 1250 | BH25: 39994.75
C26: paypal unit | E26: 99.74 | F26: 15477.79 | H26: APR | I26: mainscourt elec | K26: 115.88 | L26: 20968.4 | O26: woodies | Q26: 103.24 | R26: 16436.82 | U26: MISU | W26: 135.64 | X26: 52060.29 | AA26: APPLEGREEN | AC26: 6.9 | AD26: 45924.42 | AG26: DES WAGES | AI26: 2561.93 | AJ26: 104217.96 | AM26: TITAN CONTAI | AO26: 2626.36 | AP26: 83689.69 | AS26: MICHAEL HARTE | AU26: 700 | AV26: 76248.91 | AY26: screw fix | BA26: 39.1 | BB26: 21128.5 | BE26: AVIVA L + P SEPA DD | BG26: 1250 | BH26: 38744.75
C27: hydraquip | E27: 223.86 | F27: 15253.93 | I27: googlegsuit | K27: 9.96 | L27: 20958.44 | O27: screwfix | Q27: 140.75 | R27: 16296.07 | U27: DHL | W27: 91.51 | X27: 51968.78 | AA27: APPLEGREEN | AC27: 13.5 | AD27: 45910.92 | AG27: DES WAGES | AI27: 2561.91 | AJ27: 101656.05 | AL27: JAN | AM27: SCREWFIX | AO27: 16.7 | AP27: 83672.99 | AS27: ATC | AU27: 905.22 | AV27: 75343.69 | AY27: screw fix | BA27: 542.95 | BB27: 20585.55 | BE27: ali express | BG27: 75.57 | BH27: 38669.18
C28: ATC | E28: 243.54 | F28: 15010.39 | I28: radionics | K28: 7.32 | L28: 20951.12 | O28: robotuni | Q28: 2504.92 | R28: 13791.15 | U28: ALU | W28: 1467.34 | X28: 50501.44 | AA28: APPLEGREEN | AC28: 46.37 | AD28: 45864.55 | AG28: GOOGLE WORKSPACE | AI28: 9.96 | AJ28: 101646.09 | AM28: INSIGHT | AO28: 246 | AP28: 83426.99 | AS28: N2 ELECTRICAL | AU28: 109.42 | AV28: 75234.27 | AY28: M LIMITED | AZ28: 20172 | BB28: 40757.55 | BE28: google works | BG28: 9.96 | BH28: 38659.22
D29: 40025.59 | E29: 25015.2 | I29: radionics | K29: 77.34 | L29: 20873.78 | O29: rev commi sepa | Q29: 427.9 | R29: 13363.25 | U29: EBAY | W29: 293.42 | X29: 50208.02 | AA29: SIXT | AB29: 13.36 | AD29: 45877.91 | AG29: 5121210002324482025 SP | AH29: 3928.62 | AJ29: 105574.71 | AL29: 1723.69 | AM29: ATC | AO29: 1734.69 | AP29: 81692.3 | AS29: NATIONAL AUTO SPEA DD | AU29: 51 | AV29: 75183.27 | AY29: TRADE ELEC | BA29: 40 | BB29: 40717.55 | BE29: paypal sira | BG29: 124.96 | BH29: 38534.26
I30: radionics | K30: 118.73 | L30: 20755.05 | O30: REV VAT | P30: 585 | R30: 13948.25 | U30: EBAY | W30: 160.47 | X30: 50047.55 | AA30: REVENUE COMMI | AC30: 1298 | AD30: 44579.91 | AG30: VERN | AI30: 69.98 | AJ30: 105504.73 | AM30: GOOGLE WORKSPACE | AO30: 9.96 | AP30: 81682.34 | AS30: GOOGLE WORKSPACE | AU30: 9.96 | AV30: 75173.31 | AY30: MDI | AZ30: 1289.68 | BB30: 42007.23 | BE30: 5.12121e+17 | BF30: 34436.31 | BH30: 72970.57
I31: savoury | K31: 37.75 | L31: 20717.3 | O31: demense ele | Q31: 61.78 | R31: 13886.47 | U31: BAXTERSTORE | W31: 8 | X31: 50039.55 | AA31: HERTZ | AC31: 105.43 | AD31: 44474.48 | AG31: TESCO | AI31: 435.87 | AJ31: 105068.86 | AM31: MUSGRAVE | AO31: 149.63 | AP31: 81532.71 | AS31: M LIMITED 26040 | AT31: 1119.3 | AV31: 76292.61 | AY31: OUTLOOK ACCOU | BA31: 2579.35 | BB31: 39427.88 | BE31: National Auto SEPA DD | BG31: 48 | BH31: 72922.57
I32: sequence | K32: 2558.4 | L32: 18158.9 | O32: m limited 25052 | P32: 1088.55 | R32: 14975.02 | U32: BAXTERSTORE | W32: 12.6 | X32: 50026.95 | AA32: REVENUE COMMI | AC32: 1065.07 | AD32: 43409.41 | AG32: EFLOW | AI32: 189.93 | AJ32: 104878.93 | AM32: THE YACHT | AO32: 157.8 | AP32: 81374.91 | AS32: DC AUTOMATED | AU32: 2656.98 | AV32: 73635.63 | AY32: ALI EXPRESS | BA32: 161.73 | BB32: 39266.15 | BE32: dc automated | BG32: 396.68 | BH32: 72525.89
I33: DC automation | K33: 1999.98 | L33: 16158.92 | O33: gsuit | Q33: 9.96 | R33: 14965.06 | U33: REVENUE COMMI SEPA DD | W33: 435.09 | X33: 49591.86 | AA33: ONLINE INSIGHT | AC33: 246 | AD33: 43163.41 | AG33: DF244 DF245 DF246 DF261 | AH33: 23597.55 | AJ33: 128476.48 | AM33: RADIONICS | AO33: 7.32 | AP33: 81367.59 | AS33: AVIVA | AU33: 20000 | AV33: 53635.63 | AY33: MISU | BA33: 399.67 | BB33: 38866.48 | BE33: ebay | BF33: 187.54 | BH33: 72713.43
I34: paypal bambu | K34: 1041.38 | L34: 15117.54 | O34: radionics | Q34: 240.6 | R34: 14724.46 | U34: REVENUE COMMI SEPA DD | W34: 7441 | X34: 42150.86 | AA34: DAVE EGA | AC34: 1186.08 | AD34: 41977.33 | AG34: MICHAEL WAGES | AI34: 3767.02 | AJ34: 124709.46 | AM34: RADIONICS | AO34: 88.79 | AP34: 81278.8 | AS34: AVIVA | AU34: 16000 | AV34: 37635.63 | AY34: EFLOW | BA34: 127.23 | BB34: 38739.25 | BE34: ebay | BG34: 357.81 | BH34: 72355.62
I35: radionics | K35: 469.16 | L35: 14648.38 | O35: paypal temu | Q35: 28.32 | R35: 14696.14 | U35: TEMU | W35: 65.2 | X35: 42085.66 | AA35: M LIMITED 25092 SP (DF243) | AB35: 4182 | AD35: 46159.33 | AG35: BAMBU LAB | AI35: 81.13 | AJ35: 124628.33 | AM35: RADIONICS | AO35: 359.67 | AP35: 80919.13 | AS35: MICHAEL FARRELLY | AU35: 1600.27 | AV35: 36035.36 | AY35: RADIONICS | BA35: 7.32 | BB35: 38731.93 | BE35: ebay | BG35: 200 | BH35: 72155.62
I36: paypal parc | K36: 144.5 | L36: 14503.88 | N36: JUNE | O36: DF 204 | P36: 3271.8 | R36: 17967.94 | U36: ALI EXPRESS | W36: 127.04 | X36: 41958.62 | AA36: FINGAL CH | AC36: 209.1 | AD36: 45950.23 | AG36: MUSGRAVES | AI36: 322.36 | AJ36: 124305.97 | AM36: RADIONICS | AO36: 221.79 | AP36: 80697.34 | AS36: ATC | AU36: 183.33 | AV36: 35852.03 | AY36: RADIONICS | BA36: 14.46 | BB36: 38717.47 | BE36: misu | BG36: 243.26 | BH36: 71912.36
I37: demense elec | K37: 16.16 | L37: 14487.72 | O37: radionics | Q37: 303.79 | R37: 17664.15 | U37: ALI EXPRESS | W37: 29.17 | X37: 41929.45 | AA37: HERTZ | AC37: 6.5 | AD37: 45943.73 | AG37: BAMBU LAB | AI37: 313.23 | AJ37: 123992.74 | AM37: HYGIENE | AO37: 72.57 | AP37: 80624.77 | AS37: INSIGHT | AU37: 246 | AV37: 35606.03 | AY37: RADIONICS | BA37: 111.39 | BB37: 38606.08 | BE37: eflow | BG37: 186.83 | BH37: 71725.53
I38: City Electri | K38: 136.65 | L38: 14351.07 | O38: 512121000220472025 SP | P38: 462.48 | R38: 18126.63 | U38: SCREWFIX | W38: 858.7 | X38: 41070.75 | AA38: HERTZ | AC38: 6.5 | AD38: 45937.23 | AG38: DES WAGES | AI38: 17949.7 | AJ38: 106043.04 | AM38: INSIGHT | AO38: 246 | AP38: 80378.77 | AS38: DES FARRELLY | AU38: 2546.36 | AV38: 33059.67 | AY38: INSIGHT | BA38: 246 | BB38: 38360.08 | BE38: ppgf | BG38: 1 | BH38: 71724.53
I39: 15041 sp | J39: 9015.9 | L39: 23366.97 | O39: Paypal bamb | Q39: 110.29 | R39: 18016.34 | U39: HERTZ | W39: 105.74 | X39: 40965.01 | AA39: TOM CAMPB | AC39: 3526.07 | AD39: 42411.16 | AG39: REVEUNUE COMMI | AI39: 1121.06 | AJ39: 104921.98 | AM39: HYDRAQUIP | AO39: 1924.95 | AP39: 78453.82 | AS39: ECOPLEX | AU39: 6150 | AV39: 26909.67 | AY39: DAVE EGAN | BA39: 1890 | BB39: 36470.08 | BE39: ebay | BG39: 84.49 | BH39: 71640.04
I40: rev commi sepa | K40: 65.63 | L40: 23301.34 | O40: paypal cris | Q40: 93.43 | R40: 17922.91 | T40: AUG | U40: HENKEL | V40: 7739.9 | X40: 48704.91 | Z40: OCT | AA40: 512121000228202025 SP ( DF230 231 235) | AB40: 20731.65 | AD40: 63142.81 | AH40: 78163.31 | AI40: 48578.92 | AJ40: 0 | AM40: PAYPAL SANH | AO40: 81.52 | AP40: 78372.3 | AS40: EFLOW | AU40: 108.43 | AV40: 26801.24 | AY40: BAMBU | BA40: 310.91 | BB40: 36159.17 | BE40: ebay | BG40: 174 | BH40: 71466.04
I41: paypal bambu | K41: 79.92 | L41: 23221.42 | O41: radionics | Q41: 602.76 | R41: 17320.15 | U41: GSUIT | W41: 9.96 | X41: 48694.95 | AA41: GSUIT | AC41: 9.96 | AD41: 63132.85 | AM41: NATIONAL AUTO SEPA DD | AO41: 51 | AP41: 78321.3 | AS41: GRAND HO | AU41: 1650 | AV41: 25151.24 | AY41: QMC IP | AZ41: 1929.5 | BB41: 38088.67 | BE41: paypal unit | BG41: 36.12 | BH41: 71429.92
...

Sheet VAT OUTSTANDING
B5: MAY/JUN 26 | H5: mar/apr | N5: MAY / JUNE | T5: MAR/APR | Z5: JAN/FEB | AF5: NOV/DEC 2025 | AL5: SEP/OCT | AR5: JUL/AUG
B6: screw fix | D6: 42.55 | E6: physical | H6: MACHINE BUIL | J6: 365.27 | K6: missing invoice | N6: vendor | O6: in | P6: out | Q6: status | T6: vendor | U6: in | V6: out | W6: status | Z6: vendor | AA6: in | AB6: out | AC6: status | AF6: vendor | AG6: in | AH6: out | AI6: status | AL6: vendor | AM6: in | AN6: out | AO6: status | AR6: vendor | AS6: in | AT6: out | AU6: status | AV6: www
B7: Demence | D7: 62.26 | E7: physical | N7: TESCO | P7: 200 | Q7: y | T7: MDI | U7: 1000 | W7: Y | Z7: GOOGLE WORKSPACE | AB7: 9.96 | AC7: Y | AF7: GOOGLE WORKSPACE | AH7: 9.96 | AI7: y | AL7: SIXT | AN7: 13.36 | AO7: add in next vat return | AR7: Irish Life SEPA DD | AT7: 1250 | AU7: yy
B8: screw fix | D8: 39.1 | E8: physical | N8: TESCO | P8: 200 | Q8: y | T8: PAYPAL BOOK | V8: 137 | W8: Y | Z8: CLEVERCARDS | AB8: 3133.8 | AC8: Y | AF8: INSIGHT ACCOUNT IP | AH8: 246 | AI8: y | AL8: EXPERT BE | AN8: 233.36 | AO8: y | AR8: AVIVA L + P SEPA DD | AT8: 1250 | AU8: yy
B9: screw fix | D9: 542.95 | E9: physical | N9: TESCO | P9: 200 | Q9: y | T9: GOOGLE WORKSPACE | V9: 9.96 | W9: Y | Z9: 512121000234402026 SP | AA9: 3678.93 | AC9: Y | AF9: ATC | AH9: 590.49 | AI9: y | AL9: GSUIT | AN9: 9.96 | AO9: y | AR9: National Auto SEPA DD | AT9: 48 | AU9: yy
B10: TRADE ELEC | D10: 40 | E10: pysical | N10: TESCO | P10: 200 | Q10: y | T10: MDI | U10: 845 | W10: Y | Z10: INSIGHT | AB10: 246 | AC10: Y | AF10: 515151 | AG10: 49999.87 | AI10: y | AL10: ROBOTUNI | AN10: 248.28 | AO10: y | AR10: google works | AT10: 9.96 | AU10: y | AV10: y
B11: RADIONICS | D11: 7.32 | E11: physical | N11: TESCO | P11: 200 | Q11: y | T11: NATIONAL AUTO SPEA DD | V11: 51 | W11: Y | Z11: POS06JAN SAS | AB11: 50 | AC11: Y | AF11: BAMBU LAB | AH11: 1826.29 | AI11: y | AL11: CIRCLE K | AN11: 114.65 | AO11: y | AR11: machine buil | AT11: 134.39 | AU11: y | AV11: y
B12: RADIONICS | D12: 14.46 | E12: physical | N12: TESCO | P12: 200 | Q12: y | T12: ABGI | V12: 3690 | W12: Y | Z12: POS06JAN SAS | AB12: 529.56 | AC12: Y | AF12: HOME APPLIANCE | AH12: 379.99 | AL12: SIXT | AN12: 416.29 | AO12: y | AR12: bambu lab | AT12: 526.54 | AU12: y | AV12: y
B13: RADIONICS | D13: 111.39 | E13: physical | N13: TESCO | P13: 200 | Q13: y | T13: N2 ELECTRICAL | V13: 724.97 | W13: Y | Z13: POS06JAN SAS | AB13: 529.56 | AC13: Y | AF13: SAVOURY | AH13: 24.5 | AL13: TRAN FARRELLY | AN13: 10 | AO13: y | AR13: baldoyle ski | AT13: 360 | AU13: physical | AV13: 46210
B14: DAVE EGAN | D14: 1890 | E14: ask dad | N14: TESCO | P14: 200 | Q14: y | T14: BAMBU | V14: 241.09 | W14: Y | Z14: POS06JAN SAS | AB14: 529.56 | AC14: Y | AF14: TEMU | AH14: 111.78 | AI14: y | AL14: TRAN MICHAEL | AN14: 10 | AO14: y | AR14: hodson bay | AT14: 38.95 | AU14: cant find | AW14: 46302
B15: RADIONICS | D15: 7.32 | E15: physical | N15: TESCO | P15: 200 | Q15: y | T15: ORAL B | V15: 0.65 | W15: X | Z15: POS09JAN PAYPAL PPGF | AB15: 1 | AC15: Y | AF15: EBAY | AH15: 20.89 | AI15: y | AL15: LIDL | AN15: 22.28 | AO15: y | AR15: paypal book | AT15: 154 | AU15: yy | AV15: x
B16: RADIONICS | D16: 11.22 | E16: physical | N16: TESCO | P16: 200 | Q16: y | T16: MICHAEL FARRELLY | V16: 1599.28 | W16: Y | Z16: ALI EXPRESS | AB16: 83.04 | AC16: Y | AF16: EBAY | AH16: 9.82 | AI16: y | AL16: DEMESNE ELEC | AN16: 320.96 | AO16: y | AR16: companies re | AT16: 20 | AU16: cant find | AW16: 20/07/2026
B17: RADIONICS | D17: 10.53 | E17: physical | N17: TESCO | P17: 200 | Q17: y | T17: MICHAEL FARRELLY | V17: 1 | W17: Y | Z17: SCREWFIX | AB17: 88.65 | AC17: CHECK PHYICAL | AF17: CREA (MICKS GARAGE) | AH17: 29.94 | AI17: y | AL17: GRANGE BUIL | AN17: 28.04 | AO17: y | AR17: eflow | AT17: 53.23 | AU17: y | AV17: y
B18: QUANTUM | D18: 226.02 | E18: cant find | N18: TESCO | P18: 200 | Q18: y | T18: DES FARRELLY | V18: 2546.34 | W18: Y | Z18: ARACHAS.IE O | AB18: 1350 | AC18: y | AF18: ALS | AG18: 615 | AI18: y | AL18: SCREWFIX | AN18: 100.9 | AO18: y | AR18: insight | AT18: 246 | AU18: y | AV18: y
B19: NEPOSCHGUSD | D19: 11.43 | E19: cant find | N19: TESCO | P19: 200 | Q19: y | T19: DF269 DF273 DF266 | U19: 22145.54 | W19: Y | Z19: EATM | AB19: 94.5 | AC19: Y | AF19: BAMBU LAB | AH19: 90.07 | AI19: y | AL19: TOM CAMPB | AN19: 4920 | AO19: y | AR19: dc automated | AT19: 563.34 | AU19: y | AV19: y
B20: P0806US 1124@0.86835 | D20: 976.43 | E20: cant find | N20: TESCO | P20: 200 | Q20: y | T20: PAYPAL PPGF | V20: 1 | W20: Y | Z20: BARRIE | AB20: 166.43 | AC20: Y | AF20: EFLOW | AH20: 112.63 | AI20: y | AL20: LIDL | AN20: 17.98 | AO20: check physical | AR20: revenue commi SEPA DD | AT20: 5070 | AU20: yy
N21: TESCO | P21: 200 | Q21: y | T21: ALI EXPRESS | V21: 148.95 | W21: Y | Z21: RUBIX | AA21: 1353 | AC21: Y | AF21: SIXT | AG21: 22.27 | AI21: add on next vat return | AL21: PAYPAL CRIS | AN21: 83.7 | AO21: cant find | AR21: paypal book | AT21: 100.8 | AU21: yy
N22: HENKEL | O22: 11404.56 | Q22: y | T22: EFLOW | V22: 235.03 | W22: Y | Z22: APPLE.COM | AB22: 1038 | AC22: Y | AF22: HYGIENE SOLUTIONS | AH22: 60 | AL22: TRAN MICHAEL | AN22: 3816 | AO22: y | AR22: revenue commi SEPA DD | AT22: 629.01 | AU22: yy
N23: screw fix | P23: 42.55 | Q23: x | T23: BAMBU | V23: 176.79 | W23: Y | Z23: URBAN K | AB23: 29.7 | AF23: BAMBU LAB | AH23: 212.24 | AI23: y | AL23: M LIMITED 25091 SP (DF211) | AM23: 3136.5 | AO23: y | AR23: ecoplex | AT23: 1230 | AU23: y | AV23: 29/07/2026
N24: irish life sepa | P24: 1250 | Q24: x | T24: DF238/DF259 | U24: 3136.5 | W24: Y | Z24: PPGF | AB24: 1 | AC24: Y | AF24: REVEUNUE COMMI | AH24: 6554 | AI24: y | AL24: EFLOW | AN24: 1.23 | AO24: cant find | AR24: radionics | AT24: 36.32 | AU24: y | AV24: y
N25: Aviva L + P SEPA DD | P25: 1250 | Q25: x | T25: REVVAT | U25: 886 | W25: Y | Z25: BAMB | AB25: 236.5 | AC25: Y | AF25: REVEUNUE COMMI | AH25: 1105.94 | AI25: y | AL25: IRRITEC LTD | AN25: 50.36 | AO25: y | AR25: m limited 26073 sp | AS25: 35590.05 | AU25: y | AV25: 2 drawdowns,
N26: google | P26: 9.96 | Q26: y | T26: REVENUE COMMI | V26: 680.88 | W26: Y | Z26: REVENUE | AB26: 14367 | AC26: X | AF26: INSIGHT ACCOUNT IP | AH26: 246 | AI26: y | AL26: N2 | AN26: 277.12 | AO26: y | AR26: ebay | AT26: 249.66 | AU26: zz
B27: 500 COFFEE MACHINE LOG | C27: JULY AUG | N27: National Auto Sepa DD | P27: 51 | Q27: idk | Z27: REVENUE | AB27: 1121.07 | AC27: X | AF27: MICHAEL WAGES | AH27: 3782.15 | AI27: y | AL27: N2 | AN27: 195.29 | AO27: y | AR27: ebay | AT27: 187.54 | AU27: zz
N28: Demence | P28: 62.26 | Q28: check physical | T28: INSIGHT | V28: 246 | W28: Y | Z28: ALI EXPRESS | AB28: 32.53 | AC28: Y | AF28: MICHAEL WAGES | AH28: 3782.15 | AI28: y | AL28: DCU FEES | AN28: 6960 | AO28: csnt find | AR28: Irish Life SEPA DD | AT28: 1250 | AU28: yy
N29: screw fix | P29: 39.1 | Q29: add next vat return | T29: MICHAEL HARTE | V29: 700 | W29: CANT FIND | Z29: TITAN CONTAI | AB29: 2626.36 | AC29: y | AF29: DES WAGES | AH29: 2561.93 | AI29: y | AL29: APPLEGREEN | AN29: 6.9 | AO29: check physical | AR29: AVIVA L + P SEPA DD | AT29: 1250 | AU29: yy
N30: screw fix | P30: 542.95 | Q30: add next vat return | T30: ATC | V30: 905.22 | W30: Y | Z30: SCREWFIX | AB30: 16.7 | AC30: CHECK PHYICAL | AF30: DES WAGES | AH30: 2561.91 | AI30: y | AL30: APPLEGREEN | AN30: 13.5 | AO30: check physical | AR30: ali express | AT30: 75.57 | AU30: yy | AW30: 3
N31: M LIMITED | O31: 20172 | Q31: y | T31: N2 ELECTRICAL | V31: 109.42 | W31: Y | Z31: INSIGHT | AB31: 246 | AC31: Y | AF31: GOOGLE WORKSPACE | AH31: 9.96 | AI31: y | AL31: APPLEGREEN | AN31: 46.37 | AO31: check physical | AR31: google works | AT31: 9.96 | AU31: y | AV31: y | AY31: 34436.31
N32: TRADE ELEC | P32: 40 | Q32: check physical | T32: NATIONAL AUTO SPEA DD | V32: 51 | W32: Y | Z32: ATC | AB32: 1734.69 | AC32: Y | AF32: 5121210002324482025 SP | AG32: 3928.62 | AI32: y | AL32: SIXT | AM32: 13.36 | AR32: paypal sira | AT32: 124.96 | AU32: yy
N33: MDI | O33: 1289.68 | Q33: y | T33: GOOGLE WORKSPACE | V33: 9.96 | W33: Y | Z33: GOOGLE WORKSPACE | AB33: 9.96 | AC33: Y | AF33: VERN | AH33: 69.98 | AI33: y | AL33: REVENUE COMMI | AN33: 1298 | AO33: y | AR33: 5.12121e+17 | AS33: 34436.31 | AU33: do w/henkel website
N34: OUTLOOK ACCOU | P34: 2579.35 | Q34: y | T34: M LIMITED 26040 | U34: 1119.3 | W34: Y | Z34: MUSGRAVE | AB34: 149.63 | AF34: TESCO | AH34: 435.87 | AL34: HERTZ | AN34: 105.43 | AO34: check physical | AR34: National Auto SEPA DD | AT34: 48 | AU34: yy
N35: ALI EXPRESS | P35: 161.73 | Q35: y | T35: DC AUTOMATED | V35: 2656.98 | W35: Y | Z35: THE YACHT | AB35: 157.8 | AF35: EFLOW | AH35: 189.93 | AI35: y | AL35: REVENUE COMMI | AN35: 1065.07 | AO35: y | AR35: dc automated | AT35: 396.68 | AU35: y | AV35: y
N36: MISU | P36: 399.67 | Q36: y | T36: AVIVA | V36: 20000 | W36: Y | Z36: RADIONICS | AB36: 7.32 | AC36: Y | AF36: DF244 DF245 DF246 DF261 | AG36: 23597.55 | AI36: y | AL36: ONLINE INSIGHT | AN36: 246 | AO36: y | AR36: ebay | AS36: 187.54 | AU36: zz
N37: EFLOW | P37: 127.23 | Q37: y | T37: AVIVA | V37: 16000 | W37: Y | Z37: RADIONICS | AB37: 88.79 | AC37: Y | AF37: MICHAEL WAGES | AH37: 3767.02 | AI37: y | AL37: DAVE EGA | AN37: 1186.08 | AO37: y | AR37: ebay | AT37: 357.81 | AU37: zz
N38: RADIONICS | P38: 7.32 | Q38: include in next vat | T38: MICHAEL FARRELLY | V38: 1600.27 | W38: Y | Z38: RADIONICS | AB38: 359.67 | AC38: Y | AF38: BAMBU LAB | AH38: 81.13 | AI38: y | AL38: M LIMITED 25092 SP (DF243) | AM38: 4182 | AO38: y | AR38: ebay | AT38: 200 | AU38: zz
N39: RADIONICS | P39: 14.46 | Q39: include in next vat | T39: ATC | V39: 183.33 | W39: Y | Z39: RADIONICS | AB39: 221.79 | AC39: Y | AF39: MUSGRAVES | AH39: 322.36 | AL39: FINGAL CH | AN39: 209.1 | AO39: y | AR39: misu | AT39: 243.26 | AU39: y | AV39: y | AX39: carpel bones remember
N40: RADIONICS | P40: 111.39 | Q40: include in next vat | T40: INSIGHT | V40: 246 | W40: Y | Z40: HYGIENE | AB40: 72.57 | AF40: BAMBU LAB | AH40: 313.23 | AI40: y | AL40: HERTZ | AN40: 6.5 | AO40: y | AR40: eflow | AT40: 186.63 | AU40: y | AV40: y
N41: INSIGHT | P41: 246 | Q41: y | T41: DES FARRELLY | V41: 2546.36 | W41: Y | Z41: INSIGHT | AB41: 246 | AC41: Y | AF41: DES WAGES | AH41: 17949.7 | AI41: y | AL41: HERTZ | AN41: 6.5 | AO41: y | AR41: ppgf | AT41: 1 | AU41: yy
N42: DAVE EGAN | P42: 1890 | Q42: ask d | T42: ECOPLEX | V42: 6150 | W42: Y | Z42: HYDRAQUIP | AB42: 1924.95 | AC42: Y | AF42: REVEUNUE COMMI | AH42: 1121.06 | AI42: y | AL42: TOM CAMPB | AN42: 3526.07 | AO42: y | AR42: ebay | AT42: 84.49 | AU42: y | AV42: y
N43: BAMBU | P43: 310.91 | Q43: y | T43: EFLOW | V43: 108.43 | W43: Y | Z43: PAYPAL SANH | AB43: 81.52 | AC43: Y | AL43: 512121000228202025 SP ( DF230 231 235) | AM43: 20731.65 | AO43: y | AR43: ebay | AT43: 174 | AU43: y | AV43: y
N44: QMC IP | O44: 1929.5 | Q44: y | T44: GRAND HO | V44: 1650 | W44: CANT FIND | Z44: NATIONAL AUTO SEPA DD | AB44: 51 | AC44: ? | AL44: GSUIT | AN44: 9.96 | AO44: y | AR44: paypal unit | AT44: 36.12 | AU44: zz
...

Sheet P&L 26
B1: P&L 2026
B2: DMF Automation
E4: 0 | F4: 0 | G4: 0 | H4: 0 | I4: 0 | J4: 0 | K4: 0 | L4: 0 | M4: 0 | N4: 0 | O4: 0
B6: . | D6: 46048 | E6: 46079 | F6: 46107 | G6: 46138 | H6: 46168 | I6: 46199 | J6: 46229 | K6: 46260 | L6: 46291 | M6: 46321 | N6: 46352 | O6: 46382 | P6: ACCURALS | Q6: Total
B7: ALS | Q7: -
B8: Mapaex | F8: 3136.5 | Q8: 3136.5
B9: Oxymem | F9: 22145.54 | G9: 1119.3 | Q9: 23264.84
B10: Rubix | D10: 1353 | Q10: 1353
B11: Henkel | D11: 3678.93 | Q11: 3678.93
B12: MDI | F12: 1845 | Q12: 1845
B13: Marwan | P13: 64156.8 | Q13: 64156.8
B14: Sixt | Q14: -
B15: Machine Buil | Q15: -
B16: Total Net Revenue | D16: 5031.93 | E16: - | F16: 27127.04 | G16: 1119.3 | H16: - | I16: - | J16: - | K16: - | L16: - | M16: - | N16: - | O16: - | P16: 64156.8 | Q16: 97435.07
B18: . | D18: Jan 26 | E18: Feb 26 | F18: Mar 26 | G18: Apr 26 | H18: May 26 | I18: Jun 26 | J18: Jul 26 | K18: Aug 26 | L18: Sep 26 | M18: Oct 26 | N18: Nov 26 | O18: Dec 26 | P18: Column1 | Q18: Total
B19: DC Automation | G19: 5576.04 | Q19: 5576.04
B20: Flowcon | Q20: -
B21: Hydraquip | E21: 1924.95 | Q21: 1924.95
B22: Radionics | E22: 677.57 | Q22: 677.57
B23: Sequence Control Systems Limited | Q23: -
B24: Mainscourt Electreical Supplies | Q24: -
B25: City Electrical Factors | Q25: -
B26: Hygiene Solutions | E26: 72.57 | Q26: 72.57
B27: BPX | Q27: -
B28: Ntron | Q28: -
B29: Demense Electrical | Q29: -
B30: Dublin Plywood & Veneer | Q30: -
B31: ATC | E31: 1734.69 | F31: 905.22 | G31: 183.33 | Q31: 2823.24
B32: IFM | Q32: -
B33: Bibus | Q33: -
B34: MBS | Q34: -
B35: Vinny byrne | Q35: -
B36: Watson Marlow | Q36: -
B37: N2 Eletrical | F37: 834.39 | Q37: 834.39
B38: Ascential | Q38: -
B39: Quantum Aluminium | Q39: -
B40: Irritec LTD | Q40: -
B41: TITAN CONTAI | D41: 2626.36 | Q41: 2626.36
B42: Expert bearing | Q42: -
B43: Grange Builder Providers | Q43: -
...

Sheet BS 26
B1: Balance Sheet 2026
B2: DMF Automation
E4: 0 | F4: 0 | G4: 0 | H4: 0 | I4: 0 | J4: 0 | K4: 0 | L4: 0 | M4: 0 | N4: 0 | O4: 0
B5: . | D5: 46048 | E5: 46079 | F5: 46107 | G5: 46138 | H5: 46167 | I5: 46198 | J5: 46228 | K5: 46259 | L5: 46290 | M5: 46320 | N5: 46351 | O5: 46381
B6: Assets
B7: Current assets:
B8: Cash | D8: 83673 | E8: 59426 | F8: 75234 | G8: 15429
B9: VAT recievable
B10: debtors | G10: 64157
B11: Prepaid expenses
B12: Inventory
B13: Total current assets | D13: 83673 | E13: 59426 | F13: 75234 | G13: 79586 | H13: 0 | I13: 0 | J13: 0 | K13: 0 | L13: 0 | M13: 0 | N13: 0 | O13: 0
B15: Property & Equipment
B16: Goodwill
B17: Total Assets | D17: 83673 | E17: 59426 | F17: 75234 | G17: 79586 | H17: 0 | I17: 0 | J17: 0 | K17: 0 | L17: 0 | M17: 0 | N17: 0 | O17: 0
B19: Liabilities
B20: Current liabilities:
B21: Accounts Payable | E21: 51 | F21: 51 | G21: 51
B22: Accrued expenses | E22: 731.85 | V22: qwd
B23: VAT PAYABLE | F23: 886
D24: 15488.07 | F24: 680.88 | G24: 680.87 | R24: -886
B25: Unearned revenue | R25: -720.52033
B26: Total current liabilities | D26: 15488 | E26: 783 | F26: 1618 | G26: 732
B28: Long-term debt
B29: Other long-term liabilities
B30: Total Liabilities
B32: Shareholder's Equity
B33: Equity Capital | D33: 4473 | E33: 4473 | F33: 4473 | G33: 14473 | V33: dqw
B34: Retained Earnings | D34: 79200 | E34: 54953 | F34: 69875 | G34: 64226
B35: Shareholder's Equity | D35: 83673 | E35: 59426 | F35: 74348 | G35: 78699
B36: Total Liabilities & Shareholder's Equity | D36: 83673 | E36: 59426 | F36: 75234 | G36: 79585
D38: 0 | E38: 0 | F38: 0 | G38: 0
G39: 0
C41: 0 | D41: -18163.21
D42: 101836
D43: 86348
F44: 78614.76

Sheet BS 18M
B1: P&L 2026
B2: DMF Automation
E4: 0 | F4: 0 | G4: 0 | H4: 0 | I4: 0 | J4: 0 | K4: 0 | L4: 0 | M4: 0 | N4: 0 | O4: 0
B6: . | D6: 46047 | E6: 46078 | F6: 46106 | G6: 46137 | H6: 46167 | I6: 46198 | J6: 46228 | K6: 46259 | L6: 46290 | M6: 46320 | N6: 46351 | O6: 46381 | P6: 46048 | Q6: 46079 | R6: 46107 | S6: 46138 | T6: ACCURALS | U6: Total
B7: ALS | I7: 1595 | N7: 615
B8: Mapaex | I8: 5676 | K8: 3137 | R8: 3136.5
B9: Oxymem | D9: 25092 | E9: 123 | G9: 9016 | H9: 1089 | I9: 51617 | K9: 4224 | L9: 7319 | M9: 18647 | O9: 23598 | R9: 22145.54 | S9: 1119.3
B10: Rubix | E10: 164 | P10: 1353
B11: Henkel | I11: 462 | J11: 21772 | K11: 7740 | M11: 20732 | N11: 50000 | O11: 3929 | P11: 3678.93
B12: MDI | E12: 164 | R12: 1845
B13: Marwan | F13: 16820 | K13: 16820
B14: Sixt | L14: 13 | N14: 22
B15: Machine Buil | E15: 41
B16: Total Net Revenue | D16: 25092 | E16: 164 | F16: 16820 | G16: 9016 | H16: 1089 | I16: 59351 | J16: 21772 | K16: 31920 | L16: 7332 | M16: 39378 | N16: 50637 | O16: 27526 | P16: 5031.93 | Q16: - | R16: 27127.04 | S16: 1119.3
B18: . | D18: Jan 26 | E18: Feb 26 | F18: Mar 26 | G18: Apr 26 | H18: May 26 | I18: Jun 26 | J18: Jul 26 | K18: Aug 26 | L18: Sep 26 | M18: Oct 26 | N18: Nov 26 | O18: Dec 26 | P18: Column1 | Q18: Column2 | R18: Column3 | S18: Column4
B19: DC Automation | G19: 2000 | H19: 3085 | I19: 1295 | J19: 2472 | S19: 5576.04
B20: Flowcon | E20: 2316 | G20: 215 | K20: 2513
B21: Hydraquip | E21: 1668 | G21: 1084 | I21: 972 | J21: 2376 | Q21: 1924.95
B22: Radionics | G22: 729 | H22: 255 | I22: 1712 | K22: 120 | Q22: 677.57
B23: Sequence Control Systems Limited | F23: 3544 | G23: 2558
B24: Mainscourt Electreical Supplies | G24: 116
B25: City Electrical Factors | G25: 137
B26: Hygiene Solutions | H26: 60 | K26: 132 | N26: 60 | Q26: 72.57
B27: BPX | E27: 5421 | F27: 202 | J27: 5537
B28: Ntron | F28: 1433 | J28: 1433
B29: Demense Electrical | F29: 228 | G29: 16 | H29: 79 | L29: 321
B30: Dublin Plywood & Veneer | F30: 464
B31: ATC | E31: 2308 | I31: 410 | K31: 585 | N31: 590 | Q31: 1734.69 | R31: 905.22 | S31: 183.33
B32: IFM | E32: 1099 | H32: 101 | J32: 1179 | K32: 350
B33: Bibus | E33: 510 | J33: 475
B34: MBS
B35: Vinny byrne | I35: 41
B36: Watson Marlow | E36: 3126 | J36: 3126
B37: N2 Eletrical | J37: 397 | L37: 472 | R37: 834.39
B38: Ascential | J38: 1467
B39: Quantum Aluminium | K39: 1152
B40: Irritec LTD | L40: 50
B41: TITAN CONTAI | D41: 0 | P41: 2626.36
B42: Expert bearing | L42: 233
B43: Grange Builder Providers | L43: 28
...
